<?xml version="1.0" ?>
<mujoco model="robot_hand">
    <option timestep="0.01" />

    <!-- <actuator>
        <motor gear="10000" joint="shoulder_pitch_joint" name="actuator_shoulder_pitch" ctrlrange="-30 30" ctrllimited="true"/>
    </actuator> -->
    <asset>
        <material name="blue_" rgba="0 0 1 1" />
        <material name="green" rgba="0 1 0 1" />
        <material name="red__" rgba="1 0 0 1" />
        <material name="white" rgba="1 1 1 1" />
    </asset>


    <worldbody>
        <geom type="plane" size="15 15 0.1" pos="0 0 0" rgba=".9 0 0 1" />
        <light diffuse=".5 .5 .5" pos="0 0 3" dir="0 0 -1" />

        <body name="cube_body" pos="0 0 5">
            <geom type="box" size="0.5 0.5 0.5" rgba="0 1 0 1" />
            <body name="link_1" pos="0.7 0 0">

                <joint name="shoulder_pitch_joint" pos="0 0 0" axis="0 1 0" range="-90 90" />
                <geom type="cylinder" size="0.2 0.3" pos="0 0 0" euler="90 0 0" mass="0.2"/>

                <body name="link_2" pos="0.4 0 0">

                    <joint name="shoulder_roll_joint" pos="0 0 0" axis="0 0 1"  range="-90 90"/>
                    <geom type="cylinder" size="0.2 0.3" pos="0 0 0" euler="0 0 0" mass="0.2"/>

                    <body name="link_3" pos="0.5 0 0">

                        <joint name="shoulder_yaw_joint" pos="0 0 0" axis="1 0 0" range="-90 90"/>
                        <geom type="cylinder" size="0.2 0.3" pos="0 0 0" euler="0 90 0" mass="0.2"/>
                        
                        <body name="parallelepiped1" pos="1.2 0.225 0">
                            <geom type="box" size="0.05 0.2 1" rgba="0 1 1 1" euler="90 90 0" mass="0.2"/>
                        </body>

                        <body name="parallelepiped2" pos="1.2 -0.225 0">
                            <geom type="box" size="0.05 0.2 1" rgba="0 1 1 1" euler="90 90 0" mass="0.2"/>
                        </body>

                        <body name="elbow" pos="2 0 0">
                            
                            <joint name="elbow_pitch_joint" pos="0 0 0" axis="0 1 0" range="-45 45"/>
                            <geom type="cylinder" size="0.2 0.275" pos="0 0 0" euler="90 0 0" mass="0.2"/>

                            <body name="link_4" pos="1 0 0">
                                <geom type="cylinder" size="0.15 1" pos="0 0 0" euler="0 90 0" mass="0.2"/>
                                <site name="end_effector_site" pos="0 0 0" size="0.02" rgba="1 0 0 1"/>
                            </body>


                            <body name="end_effector" pos="2 0 0">
                                <geom type="sphere" size="0.3" rgba="1 1 1 1" mass="0.2"/>
                            </body>
                        </body>

                    </body>
                </body>
            </body>
        </body>



    </worldbody>

    <actuator>
        <motor name="shoulder_pitch_motor" joint="shoulder_pitch_joint" gear="100" ctrlrange="-2.5 2.5" ctrllimited="true" forcerange="-2.5 2.5" forcelimited="true" />
        <motor gear="1000" joint="shoulder_roll_joint" name="actuator_shoulder_roll" ctrlrange="-2.5 2.5" ctrllimited="true" forcerange="-2.5 2.5" forcelimited="true"/>
        <motor gear="1000" joint="shoulder_yaw_joint" name="actuator_shoulder_yaw" ctrlrange="-2.5 2.5" ctrllimited="true" forcerange="-2.5 2.5" forcelimited="true"/>
        <motor gear="1000" joint="elbow_pitch_joint" name="actuator_elbow_pitch" ctrlrange="-2.5 2.5" ctrllimited="true" forcerange="-2.5 2.5" forcelimited="true"/>
    </actuator>

</mujoco>
